Workbook

Sheet Training Data
A1: Training Data (n = 18)
A2: Fit all four models (polynomial, quadratic, exponential, sinusoidal) on this set only.
A3: Period | B3: Value
A4: 1 | B4: 22.27
A5: 3 | B5: 21.12
A6: 4 | B6: 20.58
A7: 5 | B7: 21.7
A8: 7 | B8: 22.11
A9: 8 | B9: 26.28
A10: 9 | B10: 27.21
A11: 11 | B11: 33.18
A12: 12 | B12: 34.74
A13: 13 | B13: 37.47
A14: 15 | B14: 41.88
A15: 16 | B15: 46.01
... A21: 24 | B21: 72.09

Sheet Test Data
A1: Test / Holdout Data (n = 6)
A2: Interior points withheld from training, within the same initial window. Used to compute test MAE.
A3: Period | B3: Value
A4: 2 | B4: 16.84
A5: 6 | B5: 23.23
A6: 10 | B6: 35.55
A7: 14 | B7: 39.62
A8: 18 | B8: 52.63
A9: 23 | B9: 70.78

Sheet Extension Data
A1: Extension Data (n = 36) — reveal AFTER initial model advocacy
A2: Periods beyond the initial window. Do not show students until after they've picked/defended a model.
A3: Period | B3: Value
A4: 25 | B4: 75.96
A5: 26 | B5: 80.57
A6: 27 | B6: 86.49
A7: 28 | B7: 85.03
A8: 29 | B8: 87.94
A9: 30 | B9: 93.28
A10: 31 | B10: 91.87
A11: 32 | B11: 95.55
A12: 33 | B12: 100.38
A13: 34 | B13: 101.82
A14: 35 | B14: 102.65
A15: 36 | B15: 105.71
... A39: 60 | B39: 118.72

Sheet Quadratic Fit
A1: Quadratic Fit: y = c2·t² + c1·t + c0 | H1: Model Coefficients (LINEST)
H2: Coef t^2 | I2: Coef t^1 | J2: Intercept
H3: {=LINEST(C6:C23,A6:B23,TRUE(),FALSE())} -> 0.088865427 | I3: 0.22800316 | J3: 19.191316
A4: Training Fit
A5: Period | B5: t^2 | C5: Value | D5: Predicted | E5: Residual | F5: |Residual|
A6: ='Training Data'!A4 -> 1 | B6: =A6^2 -> 1 | C6: ='Training Data'!B4 -> 22.27 | D6: =$J$3+$I$3*A6+$H$3*A6^2 -> 19.508184 | E6: =C6-D6 -> 2.7618158 | F6: =ABS(E6) -> 2.7618158
A7: ='Training Data'!A5 -> 3 | B7: =A7^2 -> 9 | C7: ='Training Data'!B5 -> 21.12 | D7: =$J$3+$I$3*A7+$H$3*A7^2 -> 20.675114 | E7: =C7-D7 -> 0.44488602 | F7: =ABS(E7) -> 0.44488602
A8: ='Training Data'!A6 -> 4 | B8: =A8^2 -> 16 | C8: ='Training Data'!B6 -> 20.58 | D8: =$J$3+$I$3*A8+$H$3*A8^2 -> 21.525175 | E8: =C8-D8 -> -0.94517513 | F8: =ABS(E8) -> 0.94517513
A9: ='Training Data'!A7 -> 5 | B9: =A9^2 -> 25 | C9: ='Training Data'!B7 -> 21.7 | D9: =$J$3+$I$3*A9+$H$3*A9^2 -> 22.552967 | E9: =C9-D9 -> -0.85296713 | F9: =ABS(E9) -> 0.85296713
A10: ='Training Data'!A8 -> 7 | B10: =A10^2 -> 49 | C10: ='Training Data'!B8 -> 22.11 | D10: =$J$3+$I$3*A10+$H$3*A10^2 -> 25.141744 | E10: =C10-D10 -> -3.0317437 | F10: =ABS(E10) -> 3.0317437
A11: ='Training Data'!A9 -> 8 | B11: =A11^2 -> 64 | C11: ='Training Data'!B9 -> 26.28 | D11: =$J$3+$I$3*A11+$H$3*A11^2 -> 26.702728 | E11: =C11-D11 -> -0.42272828 | F11: =ABS(E11) -> 0.42272828
A12: ='Training Data'!A10 -> 9 | B12: =A12^2 -> 81 | C12: ='Training Data'!B10 -> 27.21 | D12: =$J$3+$I$3*A12+$H$3*A12^2 -> 28.441444 | E12: =C12-D12 -> -1.2314437 | F12: =ABS(E12) -> 1.2314437
A13: ='Training Data'!A11 -> 11 | B13: =A13^2 -> 121 | C13: ='Training Data'!B11 -> 33.18 | D13: =$J$3+$I$3*A13+$H$3*A13^2 -> 32.452067 | E13: =C13-D13 -> 0.72793288 | F13: =ABS(E13) -> 0.72793288
A14: ='Training Data'!A12 -> 12 | B14: =A14^2 -> 144 | C14: ='Training Data'!B12 -> 34.74 | D14: =$J$3+$I$3*A14+$H$3*A14^2 -> 34.723975 | E14: =C14-D14 -> 0.016024894 | F14: =ABS(E14) -> 0.016024894
A15: ='Training Data'!A13 -> 13 | B15: =A15^2 -> 169 | C15: ='Training Data'!B13 -> 37.47 | D15: =$J$3+$I$3*A15+$H$3*A15^2 -> 37.173614 | E15: =C15-D15 -> 0.29638605 | F15: =ABS(E15) -> 0.29638605
A16: ='Training Data'!A14 -> 15 | B16: =A16^2 -> 225 | C16: ='Training Data'!B14 -> 41.88 | D16: =$J$3+$I$3*A16+$H$3*A16^2 -> 42.606084 | E16: =C16-D16 -> -0.72608421 | F16: =ABS(E16) -> 0.72608421
A17: ='Training Data'!A15 -> 16 | B17: =A17^2 -> 256 | C17: ='Training Data'!B15 -> 46.01 | D17: =$J$3+$I$3*A17+$H$3*A17^2 -> 45.588916 | E17: =C17-D17 -> 0.42108439 | F17: =ABS(E17) -> 0.42108439
... A23: ='Training Data'!A21 -> 24 | B23: =A23^2 -> 576 | C23: ='Training Data'!B21 -> 72.09 | D23: =$J$3+$I$3*A23+$H$3*A23^2 -> 75.849878 | E23: =C23-D23 -> -3.7598777 | F23: =ABS(E23) -> 3.7598777
A25: Test Fit
A26: Period | B26: t^2 | C26: Value | D26: Predicted | E26: Residual | F26: |Residual|
A27: ='Test Data'!A4 -> 2 | B27: =A27^2 -> 4 | C27: ='Test Data'!B4 -> 16.84 | D27: =$J$3+$I$3*A27+$H$3*A27^2 -> 20.002784 | E27: =C27-D27 -> -3.1627837 | F27: =ABS(E27) -> 3.1627837
A28: ='Test Data'!A5 -> 6 | B28: =A28^2 -> 36 | C28: ='Test Data'!B5 -> 23.23 | D28: =$J$3+$I$3*A28+$H$3*A28^2 -> 23.75849 | E28: =C28-D28 -> -0.52848999 | F28: =ABS(E28) -> 0.52848999
A29: ='Test Data'!A6 -> 10 | B29: =A29^2 -> 100 | C29: ='Test Data'!B6 -> 35.55 | D29: =$J$3+$I$3*A29+$H$3*A29^2 -> 30.35789 | E29: =C29-D29 -> 5.19211 | F29: =ABS(E29) -> 5.19211
A30: ='Test Data'!A7 -> 14 | B30: =A30^2 -> 196 | C30: ='Test Data'!B7 -> 39.62 | D30: =$J$3+$I$3*A30+$H$3*A30^2 -> 39.800984 | E30: =C30-D30 -> -0.18098365 | F30: =ABS(E30) -> 0.18098365
A31: ='Test Data'!A8 -> 18 | B31: =A31^2 -> 324 | C31: ='Test Data'!B8 -> 52.63 | D31: =$J$3+$I$3*A31+$H$3*A31^2 -> 52.087771 | E31: =C31-D31 -> 0.542229 | F31: =ABS(E31) -> 0.542229
A32: ='Test Data'!A9 -> 23 | B32: =A32^2 -> 529 | C32: ='Test Data'!B9 -> 70.78 | D32: =$J$3+$I$3*A32+$H$3*A32^2 -> 71.445199 | E32: =C32-D32 -> -0.66519942 | F32: =ABS(E32) -> 0.66519942
A34: Extension Fit
A35: Period | B35: t^2 | C35: Value | D35: Predicted | E35: Residual | F35: |Residual|
A36: ='Extension Data'!A4 -> 25 | B36: =A36^2 -> 625 | C36: ='Extension Data'!B4 -> 75.96 | D36: =$J$3+$I$3*A36+$H$3*A36^2 -> 80.432287 | E36: =C36-D36 -> -4.4722868 | F36: =ABS(E36) -> 4.4722868
A37: ='Extension Data'!A5 -> 26 | B37: =A37^2 -> 676 | C37: ='Extension Data'!B5 -> 80.57 | D37: =$J$3+$I$3*A37+$H$3*A37^2 -> 85.192427 | E37: =C37-D37 -> -4.6224267 | F37: =ABS(E37) -> 4.6224267
A38: ='Extension Data'!A6 -> 27 | B38: =A38^2 -> 729 | C38: ='Extension Data'!B6 -> 86.49 | D38: =$J$3+$I$3*A38+$H$3*A38^2 -> 90.130298 | E38: =C38-D38 -> -3.6402975 | F38: =ABS(E38) -> 3.6402975
A39: ='Extension Data'!A7 -> 28 | B39: =A39^2 -> 784 | C39: ='Extension Data'!B7 -> 85.03 | D39: =$J$3+$I$3*A39+$H$3*A39^2 -> 95.245899 | E39: =C39-D39 -> -10.215899 | F39: =ABS(E39) -> 10.215899
A40: ='Extension Data'!A8 -> 29 | B40: =A40^2 -> 841 | C40: ='Extension Data'!B8 -> 87.94 | D40: =$J$3+$I$3*A40+$H$3*A40^2 -> 100.53923 | E40: =C40-D40 -> -12.599232 | F40: =ABS(E40) -> 12.599232
A41: ='Extension Data'!A9 -> 30 | B41: =A41^2 -> 900 | C41: ='Extension Data'!B9 -> 93.28 | D41: =$J$3+$I$3*A41+$H$3*A41^2 -> 106.0103 | E41: =C41-D41 -> -12.730295 | F41: =ABS(E41) -> 12.730295
A42: ='Extension Data'!A10 -> 31 | B42: =A42^2 -> 961 | C42: ='Extension Data'!B10 -> 91.87 | D42: =$J$3+$I$3*A42+$H$3*A42^2 -> 111.65909 | E42: =C42-D42 -> -19.789089 | F42: =ABS(E42) -> 19.789089
A43: ='Extension Data'!A11 -> 32 | B43: =A43^2 -> 1024 | C43: ='Extension Data'!B11 -> 95.55 | D43: =$J$3+$I$3*A43+$H$3*A43^2 -> 117.48561 | E43: =C43-D43 -> -21.935614 | F43: =ABS(E43) -> 21.935614
A44: ='Extension Data'!A12 -> 33 | B44: =A44^2 -> 1089 | C44: ='Extension Data'!B12 -> 100.38 | D44: =$J$3+$I$3*A44+$H$3*A44^2 -> 123.48987 | E44: =C44-D44 -> -23.10987 | F44: =ABS(E44) -> 23.10987
A45: ='Extension Data'!A13 -> 34 | B45: =A45^2 -> 1156 | C45: ='Extension Data'!B13 -> 101.82 | D45: =$J$3+$I$3*A45+$H$3*A45^2 -> 129.67186 | E45: =C45-D45 -> -27.851857 | F45: =ABS(E45) -> 27.851857
A46: ='Extension Data'!A14 -> 35 | B46: =A46^2 -> 1225 | C46: ='Extension Data'!B14 -> 102.65 | D46: =$J$3+$I$3*A46+$H$3*A46^2 -> 136.03157 | E46: =C46-D46 -> -33.381575 | F46: =ABS(E46) -> 33.381575
A47: ='Extension Data'!A15 -> 36 | B47: =A47^2 -> 1296 | C47: ='Extension Data'!B15 -> 105.71 | D47: =$J$3+$I$3*A47+$H$3*A47^2 -> 142.56902 | E47: =C47-D47 -> -36.859023 | F47: =ABS(E47) -> 36.859023
...

Sheet Polynomial Fit
A1: High-Degree Polynomial Fit (degree 8) | N1: Model Coefficients (LINEST)
N2: Coef t^8 | O2: Coef t^7 | P2: Coef t^6 | Q2: Coef t^5 | R2: Coef t^4 | S2: Coef t^3 | T2: Coef t^2 | U2: Coef t^1 | V2: Intercept
N3: {=LINEST(I6:I23,A6:H23,TRUE(),FALSE())} -> -1.8053695e-07 | O3: 1.8459202e-05 | P3: -0.0007864003 | Q3: 0.018026337 | R3: -0.23905542 | S3: 1.8245166 | T3: -7.2952207 | U3: 12.766352 | V3: 15.135824
A4: Training Fit
A5: Period | B5: t^2 | C5: t^3 | D5: t^4 | E5: t^5 | F5: t^6 | G5: t^7 | H5: t^8 | I5: Value | J5: Predicted | K5: Residual | L5: |Residual|
A6: ='Training Data'!A4 -> 1 | B6: =A6^2 -> 1 | C6: =A6^3 -> 1 | D6: =A6^4 -> 1 | E6: =A6^5 -> 1 | F6: =A6^6 -> 1 | G6: =A6^7 -> 1 | H6: =A6^8 -> 1 | I6: ='Training Data'!B4 -> 22.27 | J6: =$V$3+$U$3*A6+$T$3*A6^2+$S$3*A6^3+$R$3*A6^4+$Q$3*A6^5+$P$3*A6^6+$O$3*A6^7+$N$3*A6^8 -> 22.209675 | K6: =I6-J6 -> 0.060325418 | L6: =ABS(K6) -> 0.060325418
A7: ='Training Data'!A5 -> 3 | B7: =A7^2 -> 9 | C7: =A7^3 -> 27 | D7: =A7^4 -> 81 | E7: =A7^5 -> 243 | F7: =A7^6 -> 729 | G7: =A7^7 -> 2187 | H7: =A7^8 -> 6561 | I7: ='Training Data'!B5 -> 21.12 | J7: =$V$3+$U$3*A7+$T$3*A7^2+$S$3*A7^3+$R$3*A7^4+$Q$3*A7^5+$P$3*A7^6+$O$3*A7^7+$N$3*A7^8 -> 21.522652 | K7: =I7-J7 -> -0.40265243 | L7: =ABS(K7) -> 0.40265243
A8: ='Training Data'!A6 -> 4 | B8: =A8^2 -> 16 | C8: =A8^3 -> 64 | D8: =A8^4 -> 256 | E8: =A8^5 -> 1024 | F8: =A8^6 -> 4096 | G8: =A8^7 -> 16384 | H8: =A8^8 -> 65536 | I8: ='Training Data'!B6 -> 20.58 | J8: =$V$3+$U$3*A8+$T$3*A8^2+$S$3*A8^3+$R$3*A8^4+$Q$3*A8^5+$P$3*A8^6+$O$3*A8^7+$N$3*A8^8 -> 20.577053 | K8: =I8-J8 -> 0.0029469246 | L8: =ABS(K8) -> 0.0029469246
A9: ='Training Data'!A7 -> 5 | B9: =A9^2 -> 25 | C9: =A9^3 -> 125 | D9: =A9^4 -> 625 | E9: =A9^5 -> 3125 | F9: =A9^6 -> 15625 | G9: =A9^7 -> 78125 | H9: =A9^8 -> 390625 | I9: ='Training Data'!B7 -> 21.7 | J9: =$V$3+$U$3*A9+$T$3*A9^2+$S$3*A9^3+$R$3*A9^4+$Q$3*A9^5+$P$3*A9^6+$O$3*A9^7+$N$3*A9^8 -> 20.658406 | K9: =I9-J9 -> 1.0415939 | L9: =ABS(K9) -> 1.0415939
A10: ='Training Data'!A8 -> 7 | B10: =A10^2 -> 49 | C10: =A10^3 -> 343 | D10: =A10^4 -> 2401 | E10: =A10^5 -> 16807 | F10: =A10^6 -> 117649 | G10: =A10^7 -> 823543 | H10: =A10^8 -> 5764801 | I10: ='Training Data'!B8 -> 22.11 | J10: =$V$3+$U$3*A10+$T$3*A10^2+$S$3*A10^3+$R$3*A10^4+$Q$3*A10^5+$P$3*A10^6+$O$3*A10^7+$N$3*A10^8 -> 23.482232 | K10: =I10-J10 -> -1.3722319 | L10: =ABS(K10) -> 1.3722319
A11: ='Training Data'!A9 -> 8 | B11: =A11^2 -> 64 | C11: =A11^3 -> 512 | D11: =A11^4 -> 4096 | E11: =A11^5 -> 32768 | F11: =A11^6 -> 262144 | G11: =A11^7 -> 2097152 | H11: =A11^8 -> 16777216 | I11: ='Training Data'!B9 -> 26.28 | J11: =$V$3+$U$3*A11+$T$3*A11^2+$S$3*A11^3+$R$3*A11^4+$Q$3*A11^5+$P$3*A11^6+$O$3*A11^7+$N$3*A11^8 -> 25.573756 | K11: =I11-J11 -> 0.70624436 | L11: =ABS(K11) -> 0.70624436
A12: ='Training Data'!A10 -> 9 | B12: =A12^2 -> 81 | C12: =A12^3 -> 729 | D12: =A12^4 -> 6561 | E12: =A12^5 -> 59049 | F12: =A12^6 -> 531441 | G12: =A12^7 -> 4782969 | H12: =A12^8 -> 43046721 | I12: ='Training Data'!B10 -> 27.21 | J12: =$V$3+$U$3*A12+$T$3*A12^2+$S$3*A12^3+$R$3*A12^4+$Q$3*A12^5+$P$3*A12^6+$O$3*A12^7+$N$3*A12^8 -> 27.780194 | K12: =I12-J12 -> -0.5701937 | L12: =ABS(K12) -> 0.5701937
A13: ='Training Data'!A11 -> 11 | B13: =A13^2 -> 121 | C13: =A13^3 -> 1331 | D13: =A13^4 -> 14641 | E13: =A13^5 -> 161051 | F13: =A13^6 -> 1771561 | G13: =A13^7 -> 19487171 | H13: =A13^8 -> 214358881 | I13: ='Training Data'!B11 -> 33.18 | J13: =$V$3+$U$3*A13+$T$3*A13^2+$S$3*A13^3+$R$3*A13^4+$Q$3*A13^5+$P$3*A13^6+$O$3*A13^7+$N$3*A13^8 -> 32.286623 | K13: =I13-J13 -> 0.89337723 | L13: =ABS(K13) -> 0.89337723
A14: ='Training Data'!A12 -> 12 | B14: =A14^2 -> 144 | C14: =A14^3 -> 1728 | D14: =A14^4 -> 20736 | E14: =A14^5 -> 248832 | F14: =A14^6 -> 2985984 | G14: =A14^7 -> 35831808 | H14: =A14^8 -> 429981696 | I14: ='Training Data'!B12 -> 34.74 | J14: =$V$3+$U$3*A14+$T$3*A14^2+$S$3*A14^3+$R$3*A14^4+$Q$3*A14^5+$P$3*A14^6+$O$3*A14^7+$N$3*A14^8 -> 34.681555 | K14: =I14-J14 -> 0.058444777 | L14: =ABS(K14) -> 0.058444777
A15: ='Training Data'!A13 -> 13 | B15: =A15^2 -> 169 | C15: =A15^3 -> 2197 | D15: =A15^4 -> 28561 | E15: =A15^5 -> 371293 | F15: =A15^6 -> 4826809 | G15: =A15^7 -> 62748517 | H15: =A15^8 -> 815730721 | I15: ='Training Data'!B13 -> 37.47 | J15: =$V$3+$U$3*A15+$T$3*A15^2+$S$3*A15^3+$R$3*A15^4+$Q$3*A15^5+$P$3*A15^6+$O$3*A15^7+$N$3*A15^8 -> 37.273957 | K15: =I15-J15 -> 0.19604272 | L15: =ABS(K15) -> 0.19604272
A16: ='Training Data'!A14 -> 15 | B16: =A16^2 -> 225 | C16: =A16^3 -> 3375 | D16: =A16^4 -> 50625 | E16: =A16^5 -> 759375 | F16: =A16^6 -> 11390625 | G16: =A16^7 -> 170859375 | H16: =A16^8 -> 2562890625 | I16: ='Training Data'!B14 -> 41.88 | J16: =$V$3+$U$3*A16+$T$3*A16^2+$S$3*A16^3+$R$3*A16^4+$Q$3*A16^5+$P$3*A16^6+$O$3*A16^7+$N$3*A16^8 -> 43.159371 | K16: =I16-J16 -> -1.2793707 | L16: =ABS(K16) -> 1.2793707
A17: ='Training Data'!A15 -> 16 | B17: =A17^2 -> 256 | C17: =A17^3 -> 4096 | D17: =A17^4 -> 65536 | E17: =A17^5 -> 1048576 | F17: =A17^6 -> 16777216 | G17: =A17^7 -> 268435456 | H17: =A17^8 -> 4294967296 | I17: ='Training Data'!B15 -> 46.01 | J17: =$V$3+$U$3*A17+$T$3*A17^2+$S$3*A17^3+$R$3*A17^4+$Q$3*A17^5+$P$3*A17^6+$O$3*A17^7+$N$3*A17^8 -> 46.385647 | K17: =I17-J17 -> -0.3756473 | L17: =ABS(K17) -> 0.3756473
... A23: ='Training Data'!A21 -> 24 | B23: =A23^2 -> 576 | C23: =A23^3 -> 13824 | D23: =A23^4 -> 331776 | E23: =A23^5 -> 7962624 | F23: =A23^6 -> 191102976 | G23: =A23^7 -> 4586471424 | H23: =A23^8 -> 110075314176 | I23: ='Training Data'!B21 -> 72.09 | J23: =$V$3+$U$3*A23+$T$3*A23^2+$S$3*A23^3+$R$3*A23^4+$Q$3*A23^5+$P$3*A23^6+$O$3*A23^7+$N$3*A23^8 -> 72.194838 | K23: =I23-J23 -> -0.10483757 | L23: =ABS(K23) -> 0.10483757
A25: Test Fit
A26: Period | B26: t^2 | C26: t^3 | D26: t^4 | E26: t^5 | F26: t^6 | G26: t^7 | H26: t^8 | I26: Value | J26: Predicted | K26: Residual | L26: |Residual|
A27: ='Test Data'!A4 -> 2 | B27: =A27^2 -> 4 | C27: =A27^3 -> 8 | D27: =A27^4 -> 16 | E27: =A27^5 -> 32 | F27: =A27^6 -> 64 | G27: =A27^7 -> 128 | H27: =A27^8 -> 256 | I27: ='Test Data'!B4 -> 16.84 | J27: =$V$3+$U$3*A27+$T$3*A27^2+$S$3*A27^3+$R$3*A27^4+$Q$3*A27^5+$P$3*A27^6+$O$3*A27^7+$N$3*A27^8 -> 22.787721 | K27: =I27-J27 -> -5.9477207 | L27: =ABS(K27) -> 5.9477207
A28: ='Test Data'!A5 -> 6 | B28: =A28^2 -> 36 | C28: =A28^3 -> 216 | D28: =A28^4 -> 1296 | E28: =A28^5 -> 7776 | F28: =A28^6 -> 46656 | G28: =A28^7 -> 279936 | H28: =A28^8 -> 1679616 | I28: ='Test Data'!B5 -> 23.23 | J28: =$V$3+$U$3*A28+$T$3*A28^2+$S$3*A28^3+$R$3*A28^4+$Q$3*A28^5+$P$3*A28^6+$O$3*A28^7+$N$3*A28^8 -> 21.732421 | K28: =I28-J28 -> 1.4975794 | L28: =ABS(K28) -> 1.4975794
A29: ='Test Data'!A6 -> 10 | B29: =A29^2 -> 100 | C29: =A29^3 -> 1000 | D29: =A29^4 -> 10000 | E29: =A29^5 -> 100000 | F29: =A29^6 -> 1000000 | G29: =A29^7 -> 10000000 | H29: =A29^8 -> 100000000 | I29: ='Test Data'!B6 -> 35.55 | J29: =$V$3+$U$3*A29+$T$3*A29^2+$S$3*A29^3+$R$3*A29^4+$Q$3*A29^5+$P$3*A29^6+$O$3*A29^7+$N$3*A29^8 -> 30.011411 | K29: =I29-J29 -> 5.5385891 | L29: =ABS(K29) -> 5.5385891
A30: ='Test Data'!A7 -> 14 | B30: =A30^2 -> 196 | C30: =A30^3 -> 2744 | D30: =A30^4 -> 38416 | E30: =A30^5 -> 537824 | F30: =A30^6 -> 7529536 | G30: =A30^7 -> 105413504 | H30: =A30^8 -> 1475789056 | I30: ='Test Data'!B7 -> 39.62 | J30: =$V$3+$U$3*A30+$T$3*A30^2+$S$3*A30^3+$R$3*A30^4+$Q$3*A30^5+$P$3*A30^6+$O$3*A30^7+$N$3*A30^8 -> 40.104069 | K30: =I30-J30 -> -0.48406946 | L30: =ABS(K30) -> 0.48406946
A31: ='Test Data'!A8 -> 18 | B31: =A31^2 -> 324 | C31: =A31^3 -> 5832 | D31: =A31^4 -> 104976 | E31: =A31^5 -> 1889568 | F31: =A31^6 -> 34012224 | G31: =A31^7 -> 612220032 | H31: =A31^8 -> 11019960576 | I31: ='Test Data'!B8 -> 52.63 | J31: =$V$3+$U$3*A31+$T$3*A31^2+$S$3*A31^3+$R$3*A31^4+$Q$3*A31^5+$P$3*A31^6+$O$3*A31^7+$N$3*A31^8 -> 53.127318 | K31: =I31-J31 -> -0.49731803 | L31: =ABS(K31) -> 0.49731803
A32: ='Test Data'!A9 -> 23 | B32: =A32^2 -> 529 | C32: =A32^3 -> 12167 | D32: =A32^4 -> 279841 | E32: =A32^5 -> 6436343 | F32: =A32^6 -> 148035889 | G32: =A32^7 -> 3404825447 | H32: =A32^8 -> 78310985281 | I32: ='Test Data'!B9 -> 70.78 | J32: =$V$3+$U$3*A32+$T$3*A32^2+$S$3*A32^3+$R$3*A32^4+$Q$3*A32^5+$P$3*A32^6+$O$3*A32^7+$N$3*A32^8 -> 71.530774 | K32: =I32-J32 -> -0.75077429 | L32: =ABS(K32) -> 0.75077429
A34: Extension Fit
A35: Period | B35: t^2 | C35: t^3 | D35: t^4 | E35: t^5 | F35: t^6 | G35: t^7 | H35: t^8 | I35: Value | J35: Predicted | K35: Residual | L35: |Residual|
A36: ='Extension Data'!A4 -> 25 | B36: =A36^2 -> 625 | C36: =A36^3 -> 15625 | D36: =A36^4 -> 390625 | E36: =A36^5 -> 9765625 | F36: =A36^6 -> 244140625 | G36: =A36^7 -> 6103515625 | H36: =A36^8 -> 152587890625 | I36: ='Extension Data'!B4 -> 75.96 | J36: =$V$3+$U$3*A36+$T$3*A36^2+$S$3*A36^3+$R$3*A36^4+$Q$3*A36^5+$P$3*A36^6+$O$3*A36^7+$N$3*A36^8 -> 66.292459 | K36: =I36-J36 -> 9.6675408 | L36: =ABS(K36) -> 9.6675408
A37: ='Extension Data'!A5 -> 26 | B37: =A37^2 -> 676 | C37: =A37^3 -> 17576 | D37: =A37^4 -> 456976 | E37: =A37^5 -> 11881376 | F37: =A37^6 -> 308915776 | G37: =A37^7 -> 8031810176 | H37: =A37^8 -> 208827064576 | I37: ='Extension Data'!B5 -> 80.57 | J37: =$V$3+$U$3*A37+$T$3*A37^2+$S$3*A37^3+$R$3*A37^4+$Q$3*A37^5+$P$3*A37^6+$O$3*A37^7+$N$3*A37^8 -> 46.640433 | K37: =I37-J37 -> 33.929567 | L37: =ABS(K37) -> 33.929567
A38: ='Extension Data'!A6 -> 27 | B38: =A38^2 -> 729 | C38: =A38^3 -> 19683 | D38: =A38^4 -> 531441 | E38: =A38^5 -> 14348907 | F38: =A38^6 -> 387420489 | G38: =A38^7 -> 10460353203 | H38: =A38^8 -> 282429536481 | I38: ='Extension Data'!B6 -> 86.49 | J38: =$V$3+$U$3*A38+$T$3*A38^2+$S$3*A38^3+$R$3*A38^4+$Q$3*A38^5+$P$3*A38^6+$O$3*A38^7+$N$3*A38^8 -> 1.1708776 | K38: =I38-J38 -> 85.319122 | L38: =ABS(K38) -> 85.319122
A39: ='Extension Data'!A7 -> 28 | B39: =A39^2 -> 784 | C39: =A39^3 -> 21952 | D39: =A39^4 -> 614656 | E39: =A39^5 -> 17210368 | F39: =A39^6 -> 481890304 | G39: =A39^7 -> 13492928512 | H39: =A39^8 -> 377801998336 | I39: ='Extension Data'!B7 -> 85.03 | J39: =$V$3+$U$3*A39+$T$3*A39^2+$S$3*A39^3+$R$3*A39^4+$Q$3*A39^5+$P$3*A39^6+$O$3*A39^7+$N$3*A39^8 -> -89.232064 | K39: =I39-J39 -> 174.26206 | L39: =ABS(K39) -> 174.26206
A40: ='Extension Data'!A8 -> 29 | B40: =A40^2 -> 841 | C40: =A40^3 -> 24389 | D40: =A40^4 -> 707281 | E40: =A40^5 -> 20511149 | F40: =A40^6 -> 594823321 | G40: =A40^7 -> 17249876309 | H40: =A40^8 -> 500246412961 | I40: ='Extension Data'!B8 -> 87.94 | J40: =$V$3+$U$3*A40+$T$3*A40^2+$S$3*A40^3+$R$3*A40^4+$Q$3*A40^5+$P$3*A40^6+$O$3*A40^7+$N$3*A40^8 -> -253.50504 | K40: =I40-J40 -> 341.44504 | L40: =ABS(K40) -> 341.44504
A41: ='Extension Data'!A9 -> 30 | B41: =A41^2 -> 900 | C41: =A41^3 -> 27000 | D41: =A41^4 -> 810000 | E41: =A41^5 -> 24300000 | F41: =A41^6 -> 729000000 | G41: =A41^7 -> 21870000000 | H41: =A41^8 -> 656100000000 | I41: ='Extension Data'!B9 -> 93.28 | J41: =$V$3+$U$3*A41+$T$3*A41^2+$S$3*A41^3+$R$3*A41^4+$Q$3*A41^5+$P$3*A41^6+$O$3*A41^7+$N$3*A41^8 -> -533.88769 | K41: =I41-J41 -> 627.16769 | L41: =ABS(K41) -> 627.16769
A42: ='Extension Data'!A10 -> 31 | B42: =A42^2 -> 961 | C42: =A42^3 -> 29791 | D42: =A42^4 -> 923521 | E42: =A42^5 -> 28629151 | F42: =A42^6 -> 887503681 | G42: =A42^7 -> 27512614111 | H42: =A42^8 -> 852891037441 | I42: ='Extension Data'!B10 -> 91.87 | J42: =$V$3+$U$3*A42+$T$3*A42^2+$S$3*A42^3+$R$3*A42^4+$Q$3*A42^5+$P$3*A42^6+$O$3*A42^7+$N$3*A42^8 -> -990.2214 | K42: =I42-J42 -> 1082.0914 | L42: =ABS(K42) -> 1082.0914
A43: ='Extension Data'!A11 -> 32 | B43: =A43^2 -> 1024 | C43: =A43^3 -> 32768 | D43: =A43^4 -> 1048576 | E43: =A43^5 -> 33554432 | F43: =A43^6 -> 1073741824 | G43: =A43^7 -> 34359738368 | H43: =A43^8 -> 1099511627776 | I43: ='Extension Data'!B11 -> 95.55 | J43: =$V$3+$U$3*A43+$T$3*A43^2+$S$3*A43^3+$R$3*A43^4+$Q$3*A43^5+$P$3*A43^6+$O$3*A43^7+$N$3*A43^8 -> -1705.179 | K43: =I43-J43 -> 1800.729 | L43: =ABS(K43) -> 1800.729
A44: ='Extension Data'!A12 -> 33 | B44: =A44^2 -> 1089 | C44: =A44^3 -> 35937 | D44: =A44^4 -> 1185921 | E44: =A44^5 -> 39135393 | F44: =A44^6 -> 1291467969 | G44: =A44^7 -> 42618442977 | H44: =A44^8 -> 1406408618241 | I44: ='Extension Data'!B12 -> 100.38 | J44: =$V$3+$U$3*A44+$T$3*A44^2+$S$3*A44^3+$R$3*A44^4+$Q$3*A44^5+$P$3*A44^6+$O$3*A44^7+$N$3*A44^8 -> -2790.547 | K44: =I44-J44 -> 2890.927 | L44: =ABS(K44) -> 2890.927
A45: ='Extension Data'!A13 -> 34 | B45: =A45^2 -> 1156 | C45: =A45^3 -> 39304 | D45: =A45^4 -> 1336336 | E45: =A45^5 -> 45435424 | F45: =A45^6 -> 1544804416 | G45: =A45^7 -> 52523350144 | H45: =A45^8 -> 1785793904896 | I45: ='Extension Data'!B13 -> 101.82 | J45: =$V$3+$U$3*A45+$T$3*A45^2+$S$3*A45^3+$R$3*A45^4+$Q$3*A45^5+$P$3*A45^6+$O$3*A45^7+$N$3*A45^8 -> -4394.6897 | K45: =I45-J45 -> 4496.5097 | L45: =ABS(K45) -> 4496.5097
A46: ='Extension Data'!A14 -> 35 | B46: =A46^2 -> 1225 | C46: =A46^3 -> 42875 | D46: =A46^4 -> 1500625 | E46: =A46^5 -> 52521875 | F46: =A46^6 -> 1838265625 | G46: =A46^7 -> 64339296875 | H46: =A46^8 -> 2251875390625 | I46: ='Extension Data'!B14 -> 102.65 | J46: =$V$3+$U$3*A46+$T$3*A46^2+$S$3*A46^3+$R$3*A46^4+$Q$3*A46^5+$P$3*A46^6+$O$3*A46^7+$N$3*A46^8 -> -6711.3313 | K46: =I46-J46 -> 6813.9813 | L46: =ABS(K46) -> 6813.9813
A47: ='Extension Data'!A15 -> 36 | B47: =A47^2 -> 1296 | C47: =A47^3 -> 46656 | D47: =A47^4 -> 1679616 | E47: =A47^5 -> 60466176 | F47: =A47^6 -> 2176782336 | G47: =A47^7 -> 78364164096 | H47: =A47^8 -> 2821109907456 | I47: ='Extension Data'!B15 -> 105.71 | J47: =$V$3+$U$3*A47+$T$3*A47^2+$S$3*A47^3+$R$3*A47^4+$Q$3*A47^5+$P$3*A47^6+$O$3*A47^7+$N$3*A47^8 -> -9989.7986 | K47: =I47-J47 -> 10095.509 | L47: =ABS(K47) -> 10095.509
...

Sheet Exponential Fit
A1: Exponential Fit: y = b · m^t (LOGEST) | H1: Model Coefficients (LOGEST)
H2: Base (m) | I2: Coefficient (b)
H3: {=LOGEST(B6:B23,A6:A23,TRUE(),FALSE())} -> 1.0643799 | I3: 16.745606
A4: Training Fit
A5: Period | B5: Value | C5: Predicted | D5: Residual | E5: |Residual|
A6: ='Training Data'!A4 -> 1 | B6: ='Training Data'!B4 -> 22.27 | C6: =$I$3*$H$3^A6 -> 17.823687 | D6: =B6-C6 -> 4.446313 | E6: =ABS(D6) -> 4.446313
A7: ='Training Data'!A5 -> 3 | B7: ='Training Data'!B5 -> 21.12 | C7: =$I$3*$H$3^A7 -> 20.192537 | D7: =B7-C7 -> 0.92746316 | E7: =ABS(D7) -> 0.92746316
A8: ='Training Data'!A6 -> 4 | B8: ='Training Data'!B6 -> 20.58 | C8: =$I$3*$H$3^A8 -> 21.492531 | D8: =B8-C8 -> -0.9125305 | E8: =ABS(D8) -> 0.9125305
A9: ='Training Data'!A7 -> 5 | B9: ='Training Data'!B7 -> 21.7 | C9: =$I$3*$H$3^A9 -> 22.876218 | D9: =B9-C9 -> -1.1762176 | E9: =ABS(D9) -> 1.1762176
A10: ='Training Data'!A8 -> 7 | B10: ='Training Data'!B8 -> 22.11 | C10: =$I$3*$H$3^A10 -> 25.916572 | D10: =B10-C10 -> -3.8065719 | E10: =ABS(D10) -> 3.8065719
A11: ='Training Data'!A9 -> 8 | B11: ='Training Data'!B9 -> 26.28 | C11: =$I$3*$H$3^A11 -> 27.585078 | D11: =B11-C11 -> -1.3050784 | E11: =ABS(D11) -> 1.3050784
A12: ='Training Data'!A10 -> 9 | B12: ='Training Data'!B10 -> 27.21 | C12: =$I$3*$H$3^A12 -> 29.361003 | D12: =B12-C12 -> -2.1510033 | E12: =ABS(D12) -> 2.1510033
A13: ='Training Data'!A11 -> 11 | B13: ='Training Data'!B11 -> 33.18 | C13: =$I$3*$H$3^A13 -> 33.263215 | D13: =B13-C13 -> -0.083215318 | E13: =ABS(D13) -> 0.083215318
A14: ='Training Data'!A12 -> 12 | B14: ='Training Data'!B12 -> 34.74 | C14: =$I$3*$H$3^A14 -> 35.404698 | D14: =B14-C14 -> -0.66469806 | E14: =ABS(D14) -> 0.66469806
A15: ='Training Data'!A13 -> 13 | B15: ='Training Data'!B13 -> 37.47 | C15: =$I$3*$H$3^A15 -> 37.684049 | D15: =B15-C15 -> -0.21404926 | E15: =ABS(D15) -> 0.21404926
A16: ='Training Data'!A14 -> 15 | B16: ='Training Data'!B14 -> 41.88 | C16: =$I$3*$H$3^A16 -> 42.692432 | D16: =B16-C16 -> -0.81243233 | E16: =ABS(D16) -> 0.81243233
A17: ='Training Data'!A15 -> 16 | B17: ='Training Data'!B15 -> 46.01 | C17: =$I$3*$H$3^A17 -> 45.440967 | D17: =B17-C17 -> 0.56903281 | E17: =ABS(D17) -> 0.56903281
... A23: ='Training Data'!A21 -> 24 | B23: ='Training Data'!B21 -> 72.09 | C23: =$I$3*$H$3^A23 -> 74.855016 | D23: =B23-C23 -> -2.7650164 | E23: =ABS(D23) -> 2.7650164
A25: Test Fit
A26: Period | B26: Value | C26: Predicted | D26: Residual | E26: |Residual|
A27: ='Test Data'!A4 -> 2 | B27: ='Test Data'!B4 -> 16.84 | C27: =$I$3*$H$3^A27 -> 18.971174 | D27: =B27-C27 -> -2.1311744 | E27: =ABS(D27) -> 2.1311744
A28: ='Test Data'!A5 -> 6 | B28: ='Test Data'!B5 -> 23.23 | C28: =$I$3*$H$3^A28 -> 24.348986 | D28: =B28-C28 -> -1.1189864 | E28: =ABS(D28) -> 1.1189864
A29: ='Test Data'!A6 -> 10 | B29: ='Test Data'!B6 -> 35.55 | C29: =$I$3*$H$3^A29 -> 31.251262 | D29: =B29-C29 -> 4.2987381 | E29: =ABS(D29) -> 4.2987381
A30: ='Test Data'!A7 -> 14 | B30: ='Test Data'!B7 -> 39.62 | C30: =$I$3*$H$3^A30 -> 40.110145 | D30: =B30-C30 -> -0.49014489 | E30: =ABS(D30) -> 0.49014489
A31: ='Test Data'!A8 -> 18 | B31: ='Test Data'!B8 -> 52.63 | C31: =$I$3*$H$3^A31 -> 51.48028 | D31: =B31-C31 -> 1.1497198 | E31: =ABS(D31) -> 1.1497198
A32: ='Test Data'!A9 -> 23 | B32: ='Test Data'!B9 -> 70.78 | C32: =$I$3*$H$3^A32 -> 70.327348 | D32: =B32-C32 -> 0.45265182 | E32: =ABS(D32) -> 0.45265182
A34: Extension Fit
A35: Period | B35: Value | C35: Predicted | D35: Residual | E35: |Residual|
A36: ='Extension Data'!A4 -> 25 | B36: ='Extension Data'!B4 -> 75.96 | C36: =$I$3*$H$3^A36 -> 79.674175 | D36: =B36-C36 -> -3.7141755 | E36: =ABS(D36) -> 3.7141755
A37: ='Extension Data'!A5 -> 26 | B37: ='Extension Data'!B5 -> 80.57 | C37: =$I$3*$H$3^A37 -> 84.803592 | D37: =B37-C37 -> -4.2335915 | E37: =ABS(D37) -> 4.2335915
A38: ='Extension Data'!A6 -> 27 | B38: ='Extension Data'!B6 -> 86.49 | C38: =$I$3*$H$3^A38 -> 90.263239 | D38: =B38-C38 -> -3.773239 | E38: =ABS(D38) -> 3.773239
A39: ='Extension Data'!A7 -> 28 | B39: ='Extension Data'!B7 -> 85.03 | C39: =$I$3*$H$3^A39 -> 96.074378 | D39: =B39-C39 -> -11.044378 | E39: =ABS(D39) -> 11.044378
A40: ='Extension Data'!A8 -> 29 | B40: ='Extension Data'!B8 -> 87.94 | C40: =$I$3*$H$3^A40 -> 102.25964 | D40: =B40-C40 -> -14.319638 | E40: =ABS(D40) -> 14.319638
A41: ='Extension Data'!A9 -> 30 | B41: ='Extension Data'!B9 -> 93.28 | C41: =$I$3*$H$3^A41 -> 108.8431 | D41: =B41-C41 -> -15.563104 | E41: =ABS(D41) -> 15.563104
A42: ='Extension Data'!A10 -> 31 | B42: ='Extension Data'!B10 -> 91.87 | C42: =$I$3*$H$3^A42 -> 115.85041 | D42: =B42-C42 -> -23.980413 | E42: =ABS(D42) -> 23.980413
A43: ='Extension Data'!A11 -> 32 | B43: ='Extension Data'!B11 -> 95.55 | C43: =$I$3*$H$3^A43 -> 123.30885 | D43: =B43-C43 -> -27.758852 | E43: =ABS(D43) -> 27.758852
A44: ='Extension Data'!A12 -> 33 | B44: ='Extension Data'!B12 -> 100.38 | C44: =$I$3*$H$3^A44 -> 131.24746 | D44: =B44-C44 -> -30.867464 | E44: =ABS(D44) -> 30.867464
A45: ='Extension Data'!A13 -> 34 | B45: ='Extension Data'!B13 -> 101.82 | C45: =$I$3*$H$3^A45 -> 139.69716 | D45: =B45-C45 -> -37.877164 | E45: =ABS(D45) -> 37.877164
A46: ='Extension Data'!A14 -> 35 | B46: ='Extension Data'!B14 -> 102.65 | C46: =$I$3*$H$3^A46 -> 148.69085 | D46: =B46-C46 -> -46.040854 | E46: =ABS(D46) -> 46.040854
A47: ='Extension Data'!A15 -> 36 | B47: ='Extension Data'!B15 -> 105.71 | C47: =$I$3*$H$3^A47 -> 158.26356 | D47: =B47-C47 -> -52.553558 | E47: =ABS(D47) -> 52.553558
...

Sheet Sinusoidal Fit
A1: Sinusoidal Fit: y = a + b·t + C1·sin(2π·t/T) + C2·cos(2π·t/T) | H1: Model Coefficients (LINEST)
A2: Assumed Period (T): | B2: 60 | C2: <- editable. Found by grid-searching SSE over T = 10..60 on the training data; try Solver to refine. | H2: Coef cos | I2: Coef sin | J2: Coef t | K2: Intercept
H3: {=LINEST(D6:D23,A6:C23,TRUE(),FALSE())} -> -32.171221 | I3: -10.137637 | J3: -0.093775671 | K3: 55.059777
A4: Training Fit
A5: Period | B5: sin(2πt/T) | C5: cos(2πt/T) | D5: Value | E5: Predicted | F5: Residual | G5: |Residual|
A6: ='Training Data'!A4 -> 1 | B6: =SIN(2*PI()*A6/$B$2) -> 0.10452846 | C6: =COS(2*PI()*A6/$B$2) -> 0.9945219 | D6: ='Training Data'!B4 -> 22.27 | E6: =$K$3+$J$3*A6+$I$3*B6+$H$3*C6 -> 21.911346 | F6: =D6-E6 -> 0.35865391 | G6: =ABS(F6) -> 0.35865391
A7: ='Training Data'!A5 -> 3 | B7: =SIN(2*PI()*A7/$B$2) -> 0.30901699 | C7: =COS(2*PI()*A7/$B$2) -> 0.95105652 | D7: ='Training Data'!B5 -> 21.12 | E7: =$K$3+$J$3*A7+$I$3*B7+$H$3*C7 -> 21.049098 | F7: =D7-E7 -> 0.070901523 | G7: =ABS(F7) -> 0.070901523
A8: ='Training Data'!A6 -> 4 | B8: =SIN(2*PI()*A8/$B$2) -> 0.40673664 | C8: =COS(2*PI()*A8/$B$2) -> 0.91354546 | D8: ='Training Data'!B6 -> 20.58 | E8: =$K$3+$J$3*A8+$I$3*B8+$H$3*C8 -> 21.171453 | F8: =D8-E8 -> -0.59145299 | G8: =ABS(F8) -> 0.59145299
A9: ='Training Data'!A7 -> 5 | B9: =SIN(2*PI()*A9/$B$2) -> 0.5 | C9: =COS(2*PI()*A9/$B$2) -> 0.8660254 | D9: ='Training Data'!B7 -> 21.7 | E9: =$K$3+$J$3*A9+$I$3*B9+$H$3*C9 -> 21.660985 | F9: =D9-E9 -> 0.039014632 | G9: =ABS(F9) -> 0.039014632
A10: ='Training Data'!A8 -> 7 | B10: =SIN(2*PI()*A10/$B$2) -> 0.66913061 | C10: =COS(2*PI()*A10/$B$2) -> 0.74314483 | D10: ='Training Data'!B8 -> 22.11 | E10: =$K$3+$J$3*A10+$I$3*B10+$H$3*C10 -> 23.712067 | F10: =D10-E10 -> -1.6020675 | G10: =ABS(F10) -> 1.6020675
A11: ='Training Data'!A9 -> 8 | B11: =SIN(2*PI()*A11/$B$2) -> 0.74314483 | C11: =COS(2*PI()*A11/$B$2) -> 0.66913061 | D11: ='Training Data'!B9 -> 26.28 | E11: =$K$3+$J$3*A11+$I$3*B11+$H$3*C11 -> 25.24909 | F11: =D11-E11 -> 1.0309097 | G11: =ABS(F11) -> 1.0309097
A12: ='Training Data'!A10 -> 9 | B12: =SIN(2*PI()*A12/$B$2) -> 0.80901699 | C12: =COS(2*PI()*A12/$B$2) -> 0.58778525 | D12: ='Training Data'!B10 -> 27.21 | E12: =$K$3+$J$3*A12+$I$3*B12+$H$3*C12 -> 27.104506 | F12: =D12-E12 -> 0.10549421 | G12: =ABS(F12) -> 0.10549421
A13: ='Training Data'!A11 -> 11 | B13: =SIN(2*PI()*A13/$B$2) -> 0.91354546 | C13: =COS(2*PI()*A13/$B$2) -> 0.40673664 | D13: ='Training Data'!B11 -> 33.18 | E13: =$K$3+$J$3*A13+$I$3*B13+$H$3*C13 -> 31.681838 | F13: =D13-E13 -> 1.4981624 | G13: =ABS(F13) -> 1.4981624
A14: ='Training Data'!A12 -> 12 | B14: =SIN(2*PI()*A14/$B$2) -> 0.95105652 | C14: =COS(2*PI()*A14/$B$2) -> 0.30901699 | D14: ='Training Data'!B12 -> 34.74 | E14: =$K$3+$J$3*A14+$I$3*B14+$H$3*C14 -> 34.351549 | F14: =D14-E14 -> 0.38845122 | G14: =ABS(F14) -> 0.38845122
A15: ='Training Data'!A13 -> 13 | B15: =SIN(2*PI()*A15/$B$2) -> 0.9781476 | C15: =COS(2*PI()*A15/$B$2) -> 0.20791169 | D15: ='Training Data'!B13 -> 37.47 | E15: =$K$3+$J$3*A15+$I$3*B15+$H$3*C15 -> 37.235815 | F15: =D15-E15 -> 0.23418544 | G15: =ABS(F15) -> 0.23418544
A16: ='Training Data'!A14 -> 15 | B16: =SIN(2*PI()*A16/$B$2) -> 1 | C16: =COS(2*PI()*A16/$B$2) -> 2.8330203e-16 | D16: ='Training Data'!B14 -> 41.88 | E16: =$K$3+$J$3*A16+$I$3*B16+$H$3*C16 -> 43.515504 | F16: =D16-E16 -> -1.6355044 | G16: =ABS(F16) -> 1.6355044
A17: ='Training Data'!A15 -> 16 | B17: =SIN(2*PI()*A17/$B$2) -> 0.9945219 | C17: =COS(2*PI()*A17/$B$2) -> -0.10452846 | D17: ='Training Data'!B15 -> 46.01 | E17: =$K$3+$J$3*A17+$I$3*B17+$H$3*C17 -> 46.840072 | F17: =D17-E17 -> -0.83007207 | G17: =ABS(F17) -> 0.83007207
... A23: ='Training Data'!A21 -> 24 | B23: =SIN(2*PI()*A23/$B$2) -> 0.58778525 | C23: =COS(2*PI()*A23/$B$2) -> -0.80901699 | D23: ='Training Data'!B21 -> 72.09 | E23: =$K$3+$J$3*A23+$I$3*B23+$H$3*C23 -> 72.877471 | F23: =D23-E23 -> -0.78747138 | G23: =ABS(F23) -> 0.78747138
A25: Test Fit
A26: Period | B26: sin(2πt/T) | C26: cos(2πt/T) | D26: Value | E26: Predicted | F26: Residual | G26: |Residual|
A27: ='Test Data'!A4 -> 2 | B27: =SIN(2*PI()*A27/$B$2) -> 0.20791169 | C27: =COS(2*PI()*A27/$B$2) -> 0.9781476 | D27: ='Test Data'!B4 -> 16.84 | E27: =$K$3+$J$3*A27+$I$3*B27+$H$3*C27 -> 21.29629 | F27: =D27-E27 -> -4.4562898 | G27: =ABS(F27) -> 4.4562898
A28: ='Test Data'!A5 -> 6 | B28: =SIN(2*PI()*A28/$B$2) -> 0.58778525 | C28: =COS(2*PI()*A28/$B$2) -> 0.80901699 | D28: ='Test Data'!B5 -> 23.23 | E28: =$K$3+$J$3*A28+$I$3*B28+$H$3*C28 -> 22.511305 | F28: =D28-E28 -> 0.71869523 | G28: =ABS(F28) -> 0.71869523
A29: ='Test Data'!A6 -> 10 | B29: =SIN(2*PI()*A29/$B$2) -> 0.8660254 | C29: =COS(2*PI()*A29/$B$2) -> 0.5 | D29: ='Test Data'!B6 -> 35.55 | E29: =$K$3+$J$3*A29+$I$3*B29+$H$3*C29 -> 29.256958 | F29: =D29-E29 -> 6.2930417 | G29: =ABS(F29) -> 6.2930417
A30: ='Test Data'!A7 -> 14 | B30: =SIN(2*PI()*A30/$B$2) -> 0.9945219 | C30: =COS(2*PI()*A30/$B$2) -> 0.10452846 | D30: ='Test Data'!B7 -> 39.62 | E30: =$K$3+$J$3*A30+$I$3*B30+$H$3*C30 -> 40.302007 | F30: =D30-E30 -> -0.68200687 | G30: =ABS(F30) -> 0.68200687
A31: ='Test Data'!A8 -> 18 | B31: =SIN(2*PI()*A31/$B$2) -> 0.95105652 | C31: =COS(2*PI()*A31/$B$2) -> -0.30901699 | D31: ='Test Data'!B8 -> 52.63 | E31: =$K$3+$J$3*A31+$I$3*B31+$H$3*C31 -> 53.671803 | F31: =D31-E31 -> -1.0418027 | G31: =ABS(F31) -> 1.0418027
A32: ='Test Data'!A9 -> 23 | B32: =SIN(2*PI()*A32/$B$2) -> 0.66913061 | C32: =COS(2*PI()*A32/$B$2) -> -0.74314483 | D32: ='Test Data'!B9 -> 70.78 | E32: =$K$3+$J$3*A32+$I$3*B32+$H$3*C32 -> 70.027409 | F32: =D32-E32 -> 0.75259074 | G32: =ABS(F32) -> 0.75259074
A34: Extension Fit
A35: Period | B35: sin(2πt/T) | C35: cos(2πt/T) | D35: Value | E35: Predicted | F35: Residual | G35: |Residual|
A36: ='Extension Data'!A4 -> 25 | B36: =SIN(2*PI()*A36/$B$2) -> 0.5 | C36: =COS(2*PI()*A36/$B$2) -> -0.8660254 | D36: ='Extension Data'!B4 -> 75.96 | E36: =$K$3+$J$3*A36+$I$3*B36+$H$3*C36 -> 75.507661 | F36: =D36-E36 -> 0.45233911 | G36: =ABS(F36) -> 0.45233911
A37: ='Extension Data'!A5 -> 26 | B37: =SIN(2*PI()*A37/$B$2) -> 0.40673664 | C37: =COS(2*PI()*A37/$B$2) -> -0.91354546 | D37: ='Extension Data'!B5 -> 80.57 | E37: =$K$3+$J$3*A37+$I$3*B37+$H$3*C37 -> 77.888133 | F37: =D37-E37 -> 2.6818665 | G37: =ABS(F37) -> 2.6818665
A38: ='Extension Data'!A6 -> 27 | B38: =SIN(2*PI()*A38/$B$2) -> 0.30901699 | C38: =COS(2*PI()*A38/$B$2) -> -0.95105652 | D38: ='Extension Data'!B6 -> 86.49 | E38: =$K$3+$J$3*A38+$I$3*B38+$H$3*C38 -> 79.991781 | F38: =D38-E38 -> 6.4982193 | G38: =ABS(F38) -> 6.4982193
A39: ='Extension Data'!A7 -> 28 | B39: =SIN(2*PI()*A39/$B$2) -> 0.20791169 | C39: =COS(2*PI()*A39/$B$2) -> -0.9781476 | D39: ='Extension Data'!B7 -> 85.03 | E39: =$K$3+$J$3*A39+$I$3*B39+$H$3*C39 -> 81.794527 | F39: =D39-E39 -> 3.2354728 | G39: =ABS(F39) -> 3.2354728
A40: ='Extension Data'!A8 -> 29 | B40: =SIN(2*PI()*A40/$B$2) -> 0.10452846 | C40: =COS(2*PI()*A40/$B$2) -> -0.9945219 | D40: ='Extension Data'!B8 -> 87.94 | E40: =$K$3+$J$3*A40+$I$3*B40+$H$3*C40 -> 83.275594 | F40: =D40-E40 -> 4.6644058 | G40: =ABS(F40) -> 4.6644058
A41: ='Extension Data'!A9 -> 30 | B41: =SIN(2*PI()*A41/$B$2) -> 5.6660406e-16 | C41: =COS(2*PI()*A41/$B$2) -> -1 | D41: ='Extension Data'!B9 -> 93.28 | E41: =$K$3+$J$3*A41+$I$3*B41+$H$3*C41 -> 84.417728 | F41: =D41-E41 -> 8.8622724 | G41: =ABS(F41) -> 8.8622724
A42: ='Extension Data'!A10 -> 31 | B42: =SIN(2*PI()*A42/$B$2) -> -0.10452846 | C42: =COS(2*PI()*A42/$B$2) -> -0.9945219 | D42: ='Extension Data'!B10 -> 91.87 | E42: =$K$3+$J$3*A42+$I$3*B42+$H$3*C42 -> 85.207386 | F42: =D42-E42 -> 6.6626138 | G42: =ABS(F42) -> 6.6626138
A43: ='Extension Data'!A11 -> 32 | B43: =SIN(2*PI()*A43/$B$2) -> -0.20791169 | C43: =COS(2*PI()*A43/$B$2) -> -0.9781476 | D43: ='Extension Data'!B11 -> 95.55 | E43: =$K$3+$J$3*A43+$I$3*B43+$H$3*C43 -> 85.634891 | F43: =D43-E43 -> 9.9151088 | G43: =ABS(F43) -> 9.9151088
A44: ='Extension Data'!A12 -> 33 | B44: =SIN(2*PI()*A44/$B$2) -> -0.30901699 | C44: =COS(2*PI()*A44/$B$2) -> -0.95105652 | D44: ='Extension Data'!B12 -> 100.38 | E44: =$K$3+$J$3*A44+$I$3*B44+$H$3*C44 -> 85.694531 | F44: =D44-E44 -> 14.685469 | G44: =ABS(F44) -> 14.685469
A45: ='Extension Data'!A13 -> 34 | B45: =SIN(2*PI()*A45/$B$2) -> -0.40673664 | C45: =COS(2*PI()*A45/$B$2) -> -0.91354546 | D45: ='Extension Data'!B13 -> 101.82 | E45: =$K$3+$J$3*A45+$I$3*B45+$H$3*C45 -> 85.384625 | F45: =D45-E45 -> 16.435375 | G45: =ABS(F45) -> 16.435375
A46: ='Extension Data'!A14 -> 35 | B46: =SIN(2*PI()*A46/$B$2) -> -0.5 | C46: =COS(2*PI()*A46/$B$2) -> -0.8660254 | D46: ='Extension Data'!B14 -> 102.65 | E46: =$K$3+$J$3*A46+$I$3*B46+$H$3*C46 -> 84.707542 | F46: =D46-E46 -> 17.942458 | G46: =ABS(F46) -> 17.942458
A47: ='Extension Data'!A15 -> 36 | B47: =SIN(2*PI()*A47/$B$2) -> -0.58778525 | C47: =COS(2*PI()*A47/$B$2) -> -0.80901699 | D47: ='Extension Data'!B15 -> 105.71 | E47: =$K$3+$J$3*A47+$I$3*B47+$H$3*C47 -> 83.669671 | F47: =D47-E47 -> 22.040329 | G47: =ABS(F47) -> 22.040329
...

Sheet Model Comparison
A1: Model Comparison | H1: Full-Range Comparison (Period 1-60)
A2: All values below are formulas pulling from each model's fit tab — nothing is hardcoded. | H2: Period | I2: Actual | J2: Quadratic Pred. | K2: Exponential Pred. | L2: Sinusoidal Pred.
H3: 1 | I3: =IFERROR(INDEX('Training Data'!$B$4:$B$21,MATCH(H3,'Training Data'!$A$4:$A$21,0)),IFERROR(INDEX('Test Data'!$B$4:$B$9,MATCH(H3,'Test Data'!$A$4:$A$9,0)),INDEX('Extension Data'!$B$4:$B$39,MATCH(H3,'Extension Data'!$A$4:$A$39,0)))) -> 22.27 | J3: ='Quadratic Fit'!$J$3+'Quadratic Fit'!$I$3*H3+'Quadratic Fit'!$H$3*H3^2 -> 19.508184 | K3: ='Exponential Fit'!$I$3*'Exponential Fit'!$H$3^H3 -> 17.823687 | L3: ='Sinusoidal Fit'!$K$3+'Sinusoidal Fit'!$J$3*H3+'Sinusoidal Fit'!$I$3*SIN(2*PI()*H3/'Sinusoidal Fit'!$B$2)+'Sinusoidal Fit'!$H$3*COS(2*PI()*H3/'Sinusoidal Fit'!$B$2) -> 21.911346
A4: Model | B4: Train MAE | C4: Test MAE | D4: Extension MAE | E4: Residual Autocorr (lag-1, train) | H4: 2 | I4: =IFERROR(INDEX('Training Data'!$B$4:$B$21,MATCH(H4,'Training Data'!$A$4:$A$21,0)),IFERROR(INDEX('Test Data'!$B$4:$B$9,MATCH(H4,'Test Data'!$A$4:$A$9,0)),INDEX('Extension Data'!$B$4:$B$39,MATCH(H4,'Extension Data'!$A$4:$A$39,0)))) -> 16.84 | J4: ='Quadratic Fit'!$J$3+'Quadratic Fit'!$I$3*H4+'Quadratic Fit'!$H$3*H4^2 -> 20.002784 | K4: ='Exponential Fit'!$I$3*'Exponential Fit'!$H$3^H4 -> 18.971174 | L4: ='Sinusoidal Fit'!$K$3+'Sinusoidal Fit'!$J$3*H4+'Sinusoidal Fit'!$I$3*SIN(2*PI()*H4/'Sinusoidal Fit'!$B$2)+'Sinusoidal Fit'!$H$3*COS(2*PI()*H4/'Sinusoidal Fit'!$B$2) -> 21.29629
A5: Polynomial (degree 8) | B5: ='Polynomial Fit'!B73 -> 0.70070792 | C5: ='Polynomial Fit'!B74 -> 2.4526752 | D5: ='Polynomial Fit'!B75 -> 632585.21 | E5: ='Polynomial Fit'!B76 -> -0.28356403 | H5: 3 | I5: =IFERROR(INDEX('Training Data'!$B$4:$B$21,MATCH(H5,'Training Data'!$A$4:$A$21,0)),IFERROR(INDEX('Test Data'!$B$4:$B$9,MATCH(H5,'Test Data'!$A$4:$A$9,0)),INDEX('Extension Data'!$B$4:$B$39,MATCH(H5,'Extension Data'!$A$4:$A$39,0)))) -> 21.12 | J5: ='Quadratic Fit'!$J$3+'Quadratic Fit'!$I$3*H5+'Quadratic Fit'!$H$3*H5^2 -> 20.675114 | K5: ='Exponential Fit'!$I$3*'Exponential Fit'!$H$3^H5 -> 20.192537 | L5: ='Sinusoidal Fit'!$K$3+'Sinusoidal Fit'!$J$3*H5+'Sinusoidal Fit'!$I$3*SIN(2*PI()*H5/'Sinusoidal Fit'!$B$2)+'Sinusoidal Fit'!$H$3*COS(2*PI()*H5/'Sinusoidal Fit'!$B$2) -> 21.049098
A6: Quadratic | B6: ='Quadratic Fit'!B73 -> 1.2287839 | C6: ='Quadratic Fit'!B74 -> 1.711966 | D6: ='Quadratic Fit'!B75 -> 93.569133 | E6: ='Quadratic Fit'!B76 -> 0.071073593 | H6: 4 | I6: =IFERROR(INDEX('Training Data'!$B$4:$B$21,MATCH(H6,'Training Data'!$A$4:$A$21,0)),IFERROR(INDEX('Test Data'!$B$4:$B$9,MATCH(H6,'Test Data'!$A$4:$A$9,0)),INDEX('Extension Data'!$B$4:$B$39,MATCH(H6,'Extension Data'!$A$4:$A$39,0)))) -> 20.58 | J6: ='Quadratic Fit'!$J$3+'Quadratic Fit'!$I$3*H6+'Quadratic Fit'!$H$3*H6^2 -> 21.525175 | K6: ='Exponential Fit'!$I$3*'Exponential Fit'!$H$3^H6 -> 21.492531 | L6: ='Sinusoidal Fit'!$K$3+'Sinusoidal Fit'!$J$3*H6+'Sinusoidal Fit'!$I$3*SIN(2*PI()*H6/'Sinusoidal Fit'!$B$2)+'Sinusoidal Fit'!$H$3*COS(2*PI()*H6/'Sinusoidal Fit'!$B$2) -> 21.171453
A7: Exponential | B7: ='Exponential Fit'!B73 -> 1.6966545 | C7: ='Exponential Fit'!B74 -> 1.6069026 | D7: ='Exponential Fit'!B75 -> 185.104 | E7: ='Exponential Fit'!B76 -> 0.37126093 | H7: 5 | I7: =IFERROR(INDEX('Training Data'!$B$4:$B$21,MATCH(H7,'Training Data'!$A$4:$A$21,0)),IFERROR(INDEX('Test Data'!$B$4:$B$9,MATCH(H7,'Test Data'!$A$4:$A$9,0)),INDEX('Extension Data'!$B$4:$B$39,MATCH(H7,'Extension Data'!$A$4:$A$39,0)))) -> 21.7 | J7: ='Quadratic Fit'!$J$3+'Quadratic Fit'!$I$3*H7+'Quadratic Fit'!$H$3*H7^2 -> 22.552967 | K7: ='Exponential Fit'!$I$3*'Exponential Fit'!$H$3^H7 -> 22.876218 | L7: ='Sinusoidal Fit'!$K$3+'Sinusoidal Fit'!$J$3*H7+'Sinusoidal Fit'!$I$3*SIN(2*PI()*H7/'Sinusoidal Fit'!$B$2)+'Sinusoidal Fit'!$H$3*COS(2*PI()*H7/'Sinusoidal Fit'!$B$2) -> 21.660985
A8: Sinusoidal | B8: ='Sinusoidal Fit'!B73 -> 0.81619185 | C8: ='Sinusoidal Fit'!B74 -> 2.3240712 | D8: ='Sinusoidal Fit'!B75 -> 45.19524 | E8: ='Sinusoidal Fit'!B76 -> -0.18975654 | H8: 6 | I8: =IFERROR(INDEX('Training Data'!$B$4:$B$21,MATCH(H8,'Training Data'!$A$4:$A$21,0)),IFERROR(INDEX('Test Data'!$B$4:$B$9,MATCH(H8,'Test Data'!$A$4:$A$9,0)),INDEX('Extension Data'!$B$4:$B$39,MATCH(H8,'Extension Data'!$A$4:$A$39,0)))) -> 23.23 | J8: ='Quadratic Fit'!$J$3+'Quadratic Fit'!$I$3*H8+'Quadratic Fit'!$H$3*H8^2 -> 23.75849 | K8: ='Exponential Fit'!$I$3*'Exponential Fit'!$H$3^H8 -> 24.348986 | L8: ='Sinusoidal Fit'!$K$3+'Sinusoidal Fit'!$J$3*H8+'Sinusoidal Fit'!$I$3*SIN(2*PI()*H8/'Sinusoidal Fit'!$B$2)+'Sinusoidal Fit'!$H$3*COS(2*PI()*H8/'Sinusoidal Fit'!$B$2) -> 22.511305
H9: 7 | I9: =IFERROR(INDEX('Training Data'!$B$4:$B$21,MATCH(H9,'Training Data'!$A$4:$A$21,0)),IFERROR(INDEX('Test Data'!$B$4:$B$9,MATCH(H9,'Test Data'!$A$4:$A$9,0)),INDEX('Extension Data'!$B$4:$B$39,MATCH(H9,'Extension Data'!$A$4:$A$39,0)))) -> 22.11 | J9: ='Quadratic Fit'!$J$3+'Quadratic Fit'!$I$3*H9+'Quadratic Fit'!$H$3*H9^2 -> 25.141744 | K9: ='Exponential Fit'!$I$3*'Exponential Fit'!$H$3^H9 -> 25.916572 | L9: ='Sinusoidal Fit'!$K$3+'Sinusoidal Fit'!$J$3*H9+'Sinusoidal Fit'!$I$3*SIN(2*PI()*H9/'Sinusoidal Fit'!$B$2)+'Sinusoidal Fit'!$H$3*COS(2*PI()*H9/'Sinusoidal Fit'!$B$2) -> 23.712067
A10: Read this table alongside the residual-autocorrelation column: a model can have the best (lowest) MAE | H10: 8 | I10: =IFERROR(INDEX('Training Data'!$B$4:$B$21,MATCH(H10,'Training Data'!$A$4:$A$21,0)),IFERROR(INDEX('Test Data'!$B$4:$B$9,MATCH(H10,'Test Data'!$A$4:$A$9,0)),INDEX('Extension Data'!$B$4:$B$39,MATCH(H10,'Extension Data'!$A$4:$A$39,0)))) -> 26.28 | J10: ='Quadratic Fit'!$J$3+'Quadratic Fit'!$I$3*H10+'Quadratic Fit'!$H$3*H10^2 -> 26.702728 | K10: ='Exponential Fit'!$I$3*'Exponential Fit'!$H$3^H10 -> 27.585078 | L10: ='Sinusoidal Fit'!$K$3+'Sinusoidal Fit'!$J$3*H10+'Sinusoidal Fit'!$I$3*SIN(2*PI()*H10/'Sinusoidal Fit'!$B$2)+'Sinusoidal Fit'!$H$3*COS(2*PI()*H10/'Sinusoidal Fit'!$B$2) -> 25.24909
A11: and still have clearly patterned (non-random) residuals — that's the model to be suspicious of, even though | H11: 9 | I11: =IFERROR(INDEX('Training Data'!$B$4:$B$21,MATCH(H11,'Training Data'!$A$4:$A$21,0)),IFERROR(INDEX('Test Data'!$B$4:$B$9,MATCH(H11,'Test Data'!$A$4:$A$9,0)),INDEX('Extension Data'!$B$4:$B$39,MATCH(H11,'Extension Data'!$A$4:$A$39,0)))) -> 27.21 | J11: ='Quadratic Fit'!$J$3+'Quadratic Fit'!$I$3*H11+'Quadratic Fit'!$H$3*H11^2 -> 28.441444 | K11: ='Exponential Fit'!$I$3*'Exponential Fit'!$H$3^H11 -> 29.361003 | L11: ='Sinusoidal Fit'!$K$3+'Sinusoidal Fit'!$J$3*H11+'Sinusoidal Fit'!$I$3*SIN(2*PI()*H11/'Sinusoidal Fit'!$B$2)+'Sinusoidal Fit'!$H$3*COS(2*PI()*H11/'Sinusoidal Fit'!$B$2) -> 27.104506
A12: the number alone looks good. A slightly higher MAE with residuals near zero autocorrelation is the more honest fit. | H12: 10 | I12: =IFERROR(INDEX('Training Data'!$B$4:$B$21,MATCH(H12,'Training Data'!$A$4:$A$21,0)),IFERROR(INDEX('Test Data'!$B$4:$B$9,MATCH(H12,'Test Data'!$A$4:$A$9,0)),INDEX('Extension Data'!$B$4:$B$39,MATCH(H12,'Extension Data'!$A$4:$A$39,0)))) -> 35.55 | J12: ='Quadratic Fit'!$J$3+'Quadratic Fit'!$I$3*H12+'Quadratic Fit'!$H$3*H12^2 -> 30.35789 | K12: ='Exponential Fit'!$I$3*'Exponential Fit'!$H$3^H12 -> 31.251262 | L12: ='Sinusoidal Fit'!$K$3+'Sinusoidal Fit'!$J$3*H12+'Sinusoidal Fit'!$I$3*SIN(2*PI()*H12/'Sinusoidal Fit'!$B$2)+'Sinusoidal Fit'!$H$3*COS(2*PI()*H12/'Sinusoidal Fit'!$B$2) -> 29.256958
H13: 11 | I13: =IFERROR(INDEX('Training Data'!$B$4:$B$21,MATCH(H13,'Training Data'!$A$4:$A$21,0)),IFERROR(INDEX('Test Data'!$B$4:$B$9,MATCH(H13,'Test Data'!$A$4:$A$9,0)),INDEX('Extension Data'!$B$4:$B$39,MATCH(H13,'Extension Data'!$A$4:$A$39,0)))) -> 33.18 | J13: ='Quadratic Fit'!$J$3+'Quadratic Fit'!$I$3*H13+'Quadratic Fit'!$H$3*H13^2 -> 32.452067 | K13: ='Exponential Fit'!$I$3*'Exponential Fit'!$H$3^H13 -> 33.263215 | L13: ='Sinusoidal Fit'!$K$3+'Sinusoidal Fit'!$J$3*H13+'Sinusoidal Fit'!$I$3*SIN(2*PI()*H13/'Sinusoidal Fit'!$B$2)+'Sinusoidal Fit'!$H$3*COS(2*PI()*H13/'Sinusoidal Fit'!$B$2) -> 31.681838
H14: 12 | I14: =IFERROR(INDEX('Training Data'!$B$4:$B$21,MATCH(H14,'Training Data'!$A$4:$A$21,0)),IFERROR(INDEX('Test Data'!$B$4:$B$9,MATCH(H14,'Test Data'!$A$4:$A$9,0)),INDEX('Extension Data'!$B$4:$B$39,MATCH(H14,'Extension Data'!$A$4:$A$39,0)))) -> 34.74 | J14: ='Quadratic Fit'!$J$3+'Quadratic Fit'!$I$3*H14+'Quadratic Fit'!$H$3*H14^2 -> 34.723975 | K14: ='Exponential Fit'!$I$3*'Exponential Fit'!$H$3^H14 -> 35.404698 | L14: ='Sinusoidal Fit'!$K$3+'Sinusoidal Fit'!$J$3*H14+'Sinusoidal Fit'!$I$3*SIN(2*PI()*H14/'Sinusoidal Fit'!$B$2)+'Sinusoidal Fit'!$H$3*COS(2*PI()*H14/'Sinusoidal Fit'!$B$2) -> 34.351549
H15: 13 | I15: =IFERROR(INDEX('Training Data'!$B$4:$B$21,MATCH(H15,'Training Data'!$A$4:$A$21,0)),IFERROR(INDEX('Test Data'!$B$4:$B$9,MATCH(H15,'Test Data'!$A$4:$A$9,0)),INDEX('Extension Data'!$B$4:$B$39,MATCH(H15,'Extension Data'!$A$4:$A$39,0)))) -> 37.47 | J15: ='Quadratic Fit'!$J$3+'Quadratic Fit'!$I$3*H15+'Quadratic Fit'!$H$3*H15^2 -> 37.173614 | K15: ='Exponential Fit'!$I$3*'Exponential Fit'!$H$3^H15 -> 37.684049 | L15: ='Sinusoidal Fit'!$K$3+'Sinusoidal Fit'!$J$3*H15+'Sinusoidal Fit'!$I$3*SIN(2*PI()*H15/'Sinusoidal Fit'!$B$2)+'Sinusoidal Fit'!$H$3*COS(2*PI()*H15/'Sinusoidal Fit'!$B$2) -> 37.235815
H16: 14 | I16: =IFERROR(INDEX('Training Data'!$B$4:$B$21,MATCH(H16,'Training Data'!$A$4:$A$21,0)),IFERROR(INDEX('Test Data'!$B$4:$B$9,MATCH(H16,'Test Data'!$A$4:$A$9,0)),INDEX('Extension Data'!$B$4:$B$39,MATCH(H16,'Extension Data'!$A$4:$A$39,0)))) -> 39.62 | J16: ='Quadratic Fit'!$J$3+'Quadratic Fit'!$I$3*H16+'Quadratic Fit'!$H$3*H16^2 -> 39.800984 | K16: ='Exponential Fit'!$I$3*'Exponential Fit'!$H$3^H16 -> 40.110145 | L16: ='Sinusoidal Fit'!$K$3+'Sinusoidal Fit'!$J$3*H16+'Sinusoidal Fit'!$I$3*SIN(2*PI()*H16/'Sinusoidal Fit'!$B$2)+'Sinusoidal Fit'!$H$3*COS(2*PI()*H16/'Sinusoidal Fit'!$B$2) -> 40.302007
H17: 15 | I17: =IFERROR(INDEX('Training Data'!$B$4:$B$21,MATCH(H17,'Training Data'!$A$4:$A$21,0)),IFERROR(INDEX('Test Data'!$B$4:$B$9,MATCH(H17,'Test Data'!$A$4:$A$9,0)),INDEX('Extension Data'!$B$4:$B$39,MATCH(H17,'Extension Data'!$A$4:$A$39,0)))) -> 41.88 | J17: ='Quadratic Fit'!$J$3+'Quadratic Fit'!$I$3*H17+'Quadratic Fit'!$H$3*H17^2 -> 42.606084 | K17: ='Exponential Fit'!$I$3*'Exponential Fit'!$H$3^H17 -> 42.692432 | L17: ='Sinusoidal Fit'!$K$3+'Sinusoidal Fit'!$J$3*H17+'Sinusoidal Fit'!$I$3*SIN(2*PI()*H17/'Sinusoidal Fit'!$B$2)+'Sinusoidal Fit'!$H$3*COS(2*PI()*H17/'Sinusoidal Fit'!$B$2) -> 43.515504
H18: 16 | I18: =IFERROR(INDEX('Training Data'!$B$4:$B$21,MATCH(H18,'Training Data'!$A$4:$A$21,0)),IFERROR(INDEX('Test Data'!$B$4:$B$9,MATCH(H18,'Test Data'!$A$4:$A$9,0)),INDEX('Extension Data'!$B$4:$B$39,MATCH(H18,'Extension Data'!$A$4:$A$39,0)))) -> 46.01 | J18: ='Quadratic Fit'!$J$3+'Quadratic Fit'!$I$3*H18+'Quadratic Fit'!$H$3*H18^2 -> 45.588916 | K18: ='Exponential Fit'!$I$3*'Exponential Fit'!$H$3^H18 -> 45.440967 | L18: ='Sinusoidal Fit'!$K$3+'Sinusoidal Fit'!$J$3*H18+'Sinusoidal Fit'!$I$3*SIN(2*PI()*H18/'Sinusoidal Fit'!$B$2)+'Sinusoidal Fit'!$H$3*COS(2*PI()*H18/'Sinusoidal Fit'!$B$2) -> 46.840072
H19: 17 | I19: =IFERROR(INDEX('Training Data'!$B$4:$B$21,MATCH(H19,'Training Data'!$A$4:$A$21,0)),IFERROR(INDEX('Test Data'!$B$4:$B$9,MATCH(H19,'Test Data'!$A$4:$A$9,0)),INDEX('Extension Data'!$B$4:$B$39,MATCH(H19,'Extension Data'!$A$4:$A$39,0)))) -> 50.64 | J19: ='Quadratic Fit'!$J$3+'Quadratic Fit'!$I$3*H19+'Quadratic Fit'!$H$3*H19^2 -> 48.749478 | K19: ='Exponential Fit'!$I$3*'Exponential Fit'!$H$3^H19 -> 48.366452 | L19: ='Sinusoidal Fit'!$K$3+'Sinusoidal Fit'!$J$3*H19+'Sinusoidal Fit'!$I$3*SIN(2*PI()*H19/'Sinusoidal Fit'!$B$2)+'Sinusoidal Fit'!$H$3*COS(2*PI()*H19/'Sinusoidal Fit'!$B$2) -> 50.238258
H20: 18 | I20: =IFERROR(INDEX('Training Data'!$B$4:$B$21,MATCH(H20,'Training Data'!$A$4:$A$21,0)),IFERROR(INDEX('Test Data'!$B$4:$B$9,MATCH(H20,'Test Data'!$A$4:$A$9,0)),INDEX('Extension Data'!$B$4:$B$39,MATCH(H20,'Extension Data'!$A$4:$A$39,0)))) -> 52.63 | J20: ='Quadratic Fit'!$J$3+'Quadratic Fit'!$I$3*H20+'Quadratic Fit'!$H$3*H20^2 -> 52.087771 | K20: ='Exponential Fit'!$I$3*'Exponential Fit'!$H$3^H20 -> 51.48028 | L20: ='Sinusoidal Fit'!$K$3+'Sinusoidal Fit'!$J$3*H20+'Sinusoidal Fit'!$I$3*SIN(2*PI()*H20/'Sinusoidal Fit'!$B$2)+'Sinusoidal Fit'!$H$3*COS(2*PI()*H20/'Sinusoidal Fit'!$B$2) -> 53.671803
H21: 19 | I21: =IFERROR(INDEX('Training Data'!$B$4:$B$21,MATCH(H21,'Training Data'!$A$4:$A$21,0)),IFERROR(INDEX('Test Data'!$B$4:$B$9,MATCH(H21,'Test Data'!$A$4:$A$9,0)),INDEX('Extension Data'!$B$4:$B$39,MATCH(H21,'Extension Data'!$A$4:$A$39,0)))) -> 58.03 | J21: ='Quadratic Fit'!$J$3+'Quadratic Fit'!$I$3*H21+'Quadratic Fit'!$H$3*H21^2 -> 55.603795 | K21: ='Exponential Fit'!$I$3*'Exponential Fit'!$H$3^H21 -> 54.794576 | L21: ='Sinusoidal Fit'!$K$3+'Sinusoidal Fit'!$J$3*H21+'Sinusoidal Fit'!$I$3*SIN(2*PI()*H21/'Sinusoidal Fit'!$B$2)+'Sinusoidal Fit'!$H$3*COS(2*PI()*H21/'Sinusoidal Fit'!$B$2) -> 57.102061
H22: 20 | I22: =IFERROR(INDEX('Training Data'!$B$4:$B$21,MATCH(H22,'Training Data'!$A$4:$A$21,0)),IFERROR(INDEX('Test Data'!$B$4:$B$9,MATCH(H22,'Test Data'!$A$4:$A$9,0)),INDEX('Extension Data'!$B$4:$B$39,MATCH(H22,'Extension Data'!$A$4:$A$39,0)))) -> 59.31 | J22: ='Quadratic Fit'!$J$3+'Quadratic Fit'!$I$3*H22+'Quadratic Fit'!$H$3*H22^2 -> 59.29755 | K22: ='Exponential Fit'!$I$3*'Exponential Fit'!$H$3^H22 -> 58.322246 | L22: ='Sinusoidal Fit'!$K$3+'Sinusoidal Fit'!$J$3*H22+'Sinusoidal Fit'!$I$3*SIN(2*PI()*H22/'Sinusoidal Fit'!$B$2)+'Sinusoidal Fit'!$H$3*COS(2*PI()*H22/'Sinusoidal Fit'!$B$2) -> 60.490422
H23: 21 | I23: =IFERROR(INDEX('Training Data'!$B$4:$B$21,MATCH(H23,'Training Data'!$A$4:$A$21,0)),IFERROR(INDEX('Test Data'!$B$4:$B$9,MATCH(H23,'Test Data'!$A$4:$A$9,0)),INDEX('Extension Data'!$B$4:$B$39,MATCH(H23,'Extension Data'!$A$4:$A$39,0)))) -> 63.08 | J23: ='Quadratic Fit'!$J$3+'Quadratic Fit'!$I$3*H23+'Quadratic Fit'!$H$3*H23^2 -> 63.169035 | K23: ='Exponential Fit'!$I$3*'Exponential Fit'!$H$3^H23 -> 62.077027 | L23: ='Sinusoidal Fit'!$K$3+'Sinusoidal Fit'!$J$3*H23+'Sinusoidal Fit'!$I$3*SIN(2*PI()*H23/'Sinusoidal Fit'!$B$2)+'Sinusoidal Fit'!$H$3*COS(2*PI()*H23/'Sinusoidal Fit'!$B$2) -> 63.798736
H24: 22 | I24: =IFERROR(INDEX('Training Data'!$B$4:$B$21,MATCH(H24,'Training Data'!$A$4:$A$21,0)),IFERROR(INDEX('Test Data'!$B$4:$B$9,MATCH(H24,'Test Data'!$A$4:$A$9,0)),INDEX('Extension Data'!$B$4:$B$39,MATCH(H24,'Extension Data'!$A$4:$A$39,0)))) -> 69.28 | J24: ='Quadratic Fit'!$J$3+'Quadratic Fit'!$I$3*H24+'Quadratic Fit'!$H$3*H24^2 -> 67.218252 | K24: ='Exponential Fit'!$I$3*'Exponential Fit'!$H$3^H24 -> 66.07354 | L24: ='Sinusoidal Fit'!$K$3+'Sinusoidal Fit'!$J$3*H24+'Sinusoidal Fit'!$I$3*SIN(2*PI()*H24/'Sinusoidal Fit'!$B$2)+'Sinusoidal Fit'!$H$3*COS(2*PI()*H24/'Sinusoidal Fit'!$B$2) -> 66.989728
... H62: 60 | I62: =IFERROR(INDEX('Training Data'!$B$4:$B$21,MATCH(H62,'Training Data'!$A$4:$A$21,0)),IFERROR(INDEX('Test Data'!$B$4:$B$9,MATCH(H62,'Test Data'!$A$4:$A$9,0)),INDEX('Extension Data'!$B$4:$B$39,MATCH(H62,'Extension Data'!$A$4:$A$39,0)))) -> 118.72 | J62: ='Quadratic Fit'!$J$3+'Quadratic Fit'!$I$3*H62+'Quadratic Fit'!$H$3*H62^2 -> 352.78704 | K62: ='Exponential Fit'!$I$3*'Exponential Fit'!$H$3^H62 -> 707.45848 | L62: ='Sinusoidal Fit'!$K$3+'Sinusoidal Fit'!$J$3*H62+'Sinusoidal Fit'!$I$3*SIN(2*PI()*H62/'Sinusoidal Fit'!$B$2)+'Sinusoidal Fit'!$H$3*COS(2*PI()*H62/'Sinusoidal Fit'!$B$2) -> 17.262016

Sheet Instructor Notes
A1: Instructor Notes — Why This Dataset Works
A3: Story: values grow quickly, then level off into a plateau with a wobble around periods 45-60 (a saturation/seasonality pattern). Students see only periods in the Training/Test tabs (1-24); the Extension tab (25-60) is revealed only after they've picked and defended a model.
A5: Model | B5: What the workbook shows
A6: Polynomial (degree 8) | B6: Train MAE 0.70 (near-perfect fit to only 18 points). Test MAE 2.45, ~3.5x higher, even within the initial window. Extension MAE explodes to ~633,000 — a textbook overfitting blowup once asked to extrapolate. See the Polynomial Fit tab's overlay chart.
A7: Quadratic | B7: Train MAE 1.23, Test MAE 1.71 — looks fine, and slightly better than Exponential's Test MAE (1.61 is actually a hair lower — see note below). Residual autocorrelation is low (0.07, near-random) on this particular draw — check the residual scatter chart on the Quadratic Fit tab with students and look for any curve/run pattern by eye, not just the single autocorrelation number. Extension MAE 93.6 — clearly worse than the sinusoidal fit once the plateau appears.
A8: Exponential | B8: Train MAE 1.70, Test MAE 1.61 — technically the best test MAE of the four non-polynomial... no, of the three non-sinusoidal models. Residual autocorrelation is notably higher (0.37) than Quadratic's (0.07): its residuals cluster in long same-sign runs rather than scattering randomly (visible on the Exponential Fit residual chart). This is the intended pairing for the exercise: a model that 'wins' on raw MAE while quietly showing a structured, non-random residual pattern. Its Extension MAE (185.1) is also worse than Quadratic's — extrapolating an exponential compounds error fast.
A9: Sinusoidal | B9: Mediocre in-sample: Test MAE 2.32, the worst of the three non-polynomial models on the initial data — nothing here makes it look necessary yet. Once the extension is revealed, it wins decisively: Extension MAE 45.2, versus 93.6 (Quadratic) and 185.1 (Exponential). The assumed period (T=60, in the Sinusoidal Fit tab, cell B2) was found by grid search on the training data alone — with under half a cycle visible, the period is inherently underdetermined, which is itself worth discussing with students: correctly specifying the FORM of a model does not guarantee its PARAMETERS are pinned down by limited data.
A11: Where every number comes from
A12: All MAE, coefficient, and autocorrelation values live on the model tabs and are pulled together on Model Comparison — every cell is a formula (LINEST / LOGEST / AVERAGE / CORREL), so changing a value in Training Data, Test Data, or Extension Data recalculates everything downstream automatically.
